Workbook

Sheet 初級
A1: 番号 | B1: 問題 | C1: 答え | D1: ダミー1 | E1: ダミー2 | F1: ダミー3 | G1: 文字数
A2: 1 | B2: 建築家ル・コルビュジエが唱えた「近代建築の五原則」の一つである、一階部分の壁を無くし、吹き放ちにした空間のことを何というでしょう？ | C2: ピロティ | D2: ベランダ | E2: テラス | F2: パティオ | G2: =LEN(B2) -> 65
A3: 2 | B3: フランス語で「稲妻」という意味がある、細長い形に焼いたシュー生地にクリームを入れ、チョコレートをかけたお菓子は何でしょう？ | C3: エクレア | D3: カヌレ | E3: マリトッツォ | F3: ラング・ド・シャ | G3: =LEN(B3) -> 61
A4: 3 | B4: 体操選手の内村航平の好物である、「おいしさイナズマ級」のキャッチコピーでも知られる、有楽製菓株式会社のお菓子は何でしょう？ | C4: ブラックサンダー | D4: 白い恋人 | E4: メルティーキッス | F4: アルフォート | G4: =LEN(B4) -> 61
A5: 4 | B5: フェリシモが販売する500色のものが、その珍しい色の名づけとともに有名な文房具は何でしょう？ | C5: 色鉛筆 | D5: 絵具 | E5: クレヨン | F5: ボールペン | G5: =LEN(B5) -> 46
A6: 5 | B6: ファミリーマート店内でCMが流される、東京・千葉に四つのキャンパスを持ち、徹底した実学教育で知られる日本の私立大学はどこでしょう？ | C6: 帝京平成大学 | D6: 東京海洋大学 | E6: 東京藝術大学 | F6: デジタルハリウッド大学 | G6: =LEN(B6) -> 65
A7: 6 | B7: 接頭記号、国記号、出版社記号、書名記号、チェック数字の五つの要素からなる、流通の合理化などの目的で出版物に割り当てられる番号は何でしょう？ | C7: ISBNコード | D7: QRコード | E7: バーコード | F7: カラーコード | G7: =LEN(B7) -> 69
A8: 7 | B8: 長寿のお祝いの米寿、楽器のピアノの鍵盤、全天の星座から連想される、２桁の数字はいくつでしょう？ | C8: 88 | D8: 77 | E8: 99 | F8: 66 | G8: =LEN(B8) -> 47
A9: 8 | B9: 「うさぎ」や「ハチワレ」といった友達がいる、イラストレーターのナガノが生み出した、「なんかちいさくてかわいい」キャラクターは何でしょう？ | C9: ちいかわ | D9: おぱんちゅうさぎ | E9: PUI PUI モルカー | F9: ぽぅぽ | G9: =LEN(B9) -> 68
A10: 9 | B10: 『涼宮ハルヒの憂鬱』『ヴァイオレット・エヴァーガーデン』『けいおん！』など数々の人気アニメを制作しているアニメーション会社は何でしょう？ | C10: 京都アニメーション | D10: ufotable | E10: MAPPA | F10: P.A.WORKS | G10: =LEN(B10) -> 68
A11: 10 | B11: InnerSlothの宇宙人狼ゲーム『Among Us』で通常、プレイヤー同士が争う2つの陣営とは、「クルー」陣営と何でしょう？ | C11: インポスター | D11: ベント | E11: ジャッカル | F11: シェリフ | G11: =LEN(B11) -> 64
A12: 11 | B12: 「ゼロ・グラビティ」や「ムーンウォーク」などのパフォーマンスも有名な、『スリラー』『ビリー・ジーン』などの曲で知られるアメリカの歌手は誰でしょう？ | C12: マイケル・ジャクソン | D12: ビートルズ | E12: ボブ・ディラン | F12: ジミ・ヘンドリックス | G12: =LEN(B12) -> 74
A13: 12 | B13: 声優の犬山イヌコが声をあてている、アニメ『ポケットモンスター』にシリーズ初期から登場する「ばけねこポケモン」は何でしょう？ | C13: ニャース | D13: ピカチュウ | E13: イーブイ | F13: ソーナンス | G13: =LEN(B13) -> 61
A14: 13 | B14: 娘の新津ちせは子役として活動している、『天気の子』や『君の名は。』などのヒット作を手掛けたアニメーション監督は誰でしょう？ | C14: 新海誠 | D14: 細田守 | E14: 宮崎駿 | F14: 庵野秀明 | G14: =LEN(B14) -> 61
A15: 14 | B15: 朝と夕方の二度訪れる、陸と海の間の温度差が無くなり無風状態になることを何というでしょう？ | C15: 凪(なぎ) | D15: 時化(しけ) | E15: 離岸流 | F15: 嵐 | G15: =LEN(B15) -> 44
A16: 15 | B16: 同じ文字を長時間見ていると起こる、その文字の各部分がバラバラに見え、その文字が何であるか分からなくなる現象は何でしょう？ | C16: ゲシュタルト崩壊 | D16: フィラー | E16: トートロジー | F16: タイポグリセミア | G16: =LEN(中級!B15) -> 54
A17: 16 | B17: 英語では「Tongue twister」と呼ばれる、「東京特許許可局」などのような言いにくい言葉を早く間違えずに言う言葉遊びを何というでしょう？ | C17: 早口言葉 | D17: 福笑い | E17: タングラム | F17: しりとり | G17: =LEN(B17) -> 72
A18: 17 | B18: 大学生が講義を選ぶ要素の一つである、教師が学生に示す講義・授業の計画のことを何というでしょう？ | C18: シラバス | D18: レジュメ | E18: レポート | F18: プレゼンテーション | G18: =LEN(B18) -> 47
A19: 18 | B19: ファンデーションでは隠し切れないクマやシミなどに部分的に塗る、英語で「隠すもの」という意味がある化粧品は何でしょう？ | C19: コンシーラー | D19: ビューラー | E19: リップ | F19: チーク | G19: =LEN(B19) -> 58
A20: 19 | B20: よく知られている「ビューラー」は実は商標名である、まつげを挟んで上向きにそらせる化粧具の一般名称は何でしょう？ | C20: アイラッシュカーラー | D20: アイシャドウ | E20: アイブロウ | F20: アイライナー | G20: =LEN(B20) -> 55
A21: 20 | B21: アニメ『NARUTO -ナルト- 疾風伝』の『シルエット』や『BORUTO-ボルト-』の『バトンロード』などの主題歌を担当したロックバンドは何でしょう？ | C21: KANA-BOON | D21: HoneyWorks | E21: SUPER BEAVER | F21: RADWIMPS | G21: =LEN(B21) -> 76
A22: 21 | B22: ゲームにおいて、MODなどを追加せずにオリジナルの状態でプレイすることを、香料に用いられる植物の名前を使って何というでしょう？ | C22: バニラ | D22: プレーン | E22: ストレート | F22: シナモン | G22: =LEN(B22) -> 63
A23: 22 | B23: その形から「伯耆富士」の別名もある、鳥取県にある標高1,729mの中国地方の最高峰は何でしょう？ | C23: 大山 | D23: 蒜山 | E23: 三瓶山 | F23: 道後山 | G23: =LEN(B23) -> 48
A24: 23 | B24: 2013年に「信仰の対象と芸術の源泉」として世界文化遺産に登録された、標高3,776mの日本の最高峰は何でしょう？ | C24: 富士山 | D24: エベレスト | E24: キリマンジャロ | F24: ウルル | G24: =LEN(B24) -> 57
A25: 24 | B25: 「正しさとは 愚かさとは それが何か見せつけてやる」という歌いだしで始まる、歌い手・Adoのメジャーデビュー曲は何でしょう？ | C25: 『うっせぇわ』 | D25: 『踊』 | E25: 『阿修羅ちゃん』 | F25: 『ギラギラ』 | G25: =LEN(B25) -> 62
A26: 25 | B26: ステンノー、エウリュアレーという姉を持つゴルゴン三姉妹の三女で、見たものを石に変える能力を持つ、ギリシャ神話の怪物は何でしょう？ | C26: メデューサ | D26: エキドナ | E26: ケルベロス | F26: キマイラ | G26: =LEN(B26) -> 64
A27: 26 | B27: 「この街も変わらねえな」というセリフから始まり、ダジャレなどを用いてある食べ物に関するジョークを飛ばす、お笑いコンビ・スピードワゴンの井戸田潤の持ちネタは何でしょう？ | C27: ハンバーグ師匠 | D27: ひき肉です | E27: ルネッサーンス | F27: カロリーゼロ理論 | G27: =LEN(B27) -> 83
A28: 27 | B28: 開発段階では「ポポポ」という名前だった、吸い込んだ相手の特徴をコピーする能力を持つ、任天堂のゲームに登場するキャラクターは誰でしょう？ | C28: カービィ | D28: マリオ | E28: リンク | F28: インクリング | G28: =LEN(B28) -> 67
... A34: 33 | B34: 犯罪者の隠語では「弁当持ち」などと言われる、刑事裁判において、有罪判決を受けた被告人に対し、一定期間、刑の執行を先送りにすることを何というでしょう？ | C34: 執行猶予 | D34: 仮釈放 | E34: 司法取引 | F34: 無期懲役 | G34: =LEN(B34) -> 74
A35: 34 | B35: バスケットボールで、ボールを持ったまま3歩以上歩く反則を何というでしょう？ | C35: トラベリング | D35: ピボットターン | E35: アリウープ | F35: エアボール | G35: =LEN(#REF!) -> #REF!
A36: 35 | B36: その名前の由来が、銀白色の細長い体が日本刀に似ていることからとも、泳ぐ姿がまるで立っているように見えるからとも言われる魚は何でしょう？ | C36: タチウオ | D36: タツノオトシゴ | E36: リュウグウノツカイ | F36: ヤリイカ | G36: =LEN(B36) -> 67
A37: 36 | B37: 24時間経つと自動的に削除されるため手軽に投稿できるとして人気の、SNSアプリ・Instagramの機能は何でしょう？ | C37: ストーリーズ | D37: リール | E37: スレッズ | F37: サークル | G37: =LEN(B37) -> 59
A38: 37 | B38: その名には「かっこいい意気地なし」という意味がある、野田洋次郎をはじめとする4人組音楽ユニットで、これまで新海誠作品の多くで主題歌を務めたバンドは何でしょう？ | C38: RADWIMPS | D38: BUMP OF CHICKEN | E38: Mrs. GREEN APPLE | F38: KANA-BOON | G38: =LEN(B38) -> 79
A39: 38 | B39: 京都に六波羅探題が置かれるきっかけとなった、1221年、後鳥羽上皇が鎌倉幕府打倒を掲げた戦いのことを、当時の元号から何というでしょう？ | C39: 承久の乱 | D39: 嘉吉の乱 | E39: 応仁の乱 | F39: 保元の乱 | G39: =LEN(B39) -> 67
A40: 39 | B40: これより戦国時代が幕開けた、室町幕府の8代将軍・足利義政の後継者争いが原因で起こった戦いを、当時の元号から何というでしょう？ | C40: 応仁の乱 | D40: 承久の乱 | E40: 嘉吉の乱 | F40: 保元の乱 | G40: =LEN(B40) -> 62
A41: 40 | B41: ガリウムやジルコニウムなどのように、天然に存在する量が極めて少ないとされる金属のことを、「ベースメタル」に対して何というでしょう？ | C41: レアメタル | D41: レアアース | E41: 卑金属 | F41: 貴金属 | G41: =LEN(B41) -> 65
A42: 41 | B42: 海外では2人の創業者の名前から「バスキン・ロビンス」と呼ばれる、世界最大のアイスクリームチェーンは何でしょう？ | C42: サーティワン | D42: マンハッタンロール | E42: レインボーハット | F42: セブンティーンアイス | G42: =LEN(B42) -> 55
A43: 42 | B43: 狭いスペースにも印字できる「rM」という規格もある、日本のデンソーウェーブが開発した二次元コードの名称は何でしょう？ | C43: QRコード | D43: ISBNコード | E43: バーコード | F43: カラーコード | G43: =LEN(B43) -> 58
A44: 43 | B44: バレーボールで、後衛の選手がアタックラインの後ろから飛んでスパイクを打つことを何というでしょう？ | C44: バックアタック | D44: ツーアタック | E44: クイック | F44: オープン攻撃 | G44: =LEN(B44) -> 48
A45: 44 | B45: 冷たい物を食べた時に頭が「キーン」と痛くなる現象を、代表的な冷たい食べ物の名前を用いて「何頭痛」というでしょう？ | C45: アイスクリーム頭痛 | D45: かき氷頭痛 | E45: ペットボトル頭痛 | F45: ラムネ頭痛 | G45: =LEN(B45) -> 56
...

Sheet 中級
A1: 番号 | B1: 問題 | C1: 答え | D1: ダミー1 | E1: ダミー2 | F1: ダミー3 | G1: 文字数
A2: 1 | B2: 略称を「FP」という、年金・保険・投資・税制・生活設計などに関する専門知識を生かして、主に個人の資産運用に関する相談に応じる専門家のことを何というでしょう？ | C2: ファイナンシャルプランナー | D2: ファイナンシャルペアレンツ | E2: ファイナンシャルパートナー | F2: ファイナンシャルペイメント | G2: =LEN(B2) -> 78
A3: 2 | B3: フィリピンのマクタン島では、侵略者を倒した英雄として讃えられている、1521年に世界一周を試みたマゼランを打ち破った人物は誰でしょう？ | C3: ラプラプ | D3: テフテフ | E3: マフマフ | F3: カブカブ | G3: =LEN(B3) -> 67
A4: 3 | B4: フランス・ブルボン王朝の最盛期を築き、「朕は国家なり」という名言を残した、「太陽王」と称された人物は誰でしょう？ | C4: ルイ14世 | D4: ニコライ二世 | E4: ヨハン・シュトラウス二世 | F4: フェリペ二世 | G4: =LEN(B4) -> 56
A5: 4 | B5: 「英雄」と呼ばれた競走馬・ディープインパクトの息子であり、2020年には父と同じく無敗のクラシック三冠という偉業を達成した競走馬は誰でしょう？ | C5: コントレイル | D5: オルフェーヴル | E5: アーモンドアイ | F5: キタサンブラック | G5: =LEN(B5) -> 71
A6: 5 | B6: 2022年に開かれた第一回のウィニングアンサーは「ルノワール」であった、QuizKnockが主催する、高校生以下のクイズ大会は何でしょう？ | C6: 「WHAT」 | D6: 「abc」 | E6: 「EQIDEN」 | F6: 「高校生クイズ」 | G6: =LEN(B6) -> 69
A7: 6 | B7: 水島新司の野球漫画『ドカベン』は、元々は野球ではなく他のスポーツを題材にして描かれていましたが、そのスポーツとは何でしょう？ | C7: 柔道 | D7: サッカー | E7: 水泳 | F7: 相撲 | G7: =LEN(B7) -> 62
A8: 7 | B8: 「転がる石には苔が生えぬ」と同じ意味のことわざで、努力し続けている人は自然とそれが表にあらわれることを、「使っている何は光る」というでしょう？ | C8: 鍬(くわ) | D8: 鋤(すき) | E8: 鎌(かま) | F8: 鋸(のこぎり) | G8: =LEN(B8) -> 71
A9: 8 | B9: 猫除けのペットボトルでも起こる可能性がある、太陽光などの光が一点に集まることで起こる火災を何というでしょう？ | C9: 収斂火災 | D9: 爆縮火災 | E9: 集中火災 | F9: 拡散火災 | G9: =LEN(B9) -> 54
A10: 9 | B10: 結婚や相続などに関する全282条からなり、特に196・197条の「目には目を、歯には歯を」が有名な、バビロニア帝国の初代王の名前がついた法典は何でしょう？ | C10: ハンムラビ法典 | D10: ミドハト憲法 | E10: ワイマール憲法 | F10: ベバリッジ報告 | G10: =LEN(B10) -> 77
A11: 10 | B11: 2018年には有村架純主演で映画化された、過去に戻れる喫茶店「フニクリフニクラ」に訪れた客の物語を描いた、川口俊和の小説は何でしょう？ | C11: 『コーヒーが冷めないうちに』 | D11: 『博士の愛した数式』 | E11: 『告白』 | F11: 『君の膵臓をたべたい』 | G11: =LEN(B11) -> 67
A12: 11 | B12: ロゴマークには、ギリシャ神話の人魚「セイレーン」が描かれている、主力商品の「フラペチーノ」で知られるコーヒーチェーン店は何でしょう？ | C12: スターバックスコーヒー | D12: ドトールコーヒー | E12: コメダ珈琲店 | F12: タリーズコーヒー | G12: =LEN(B12) -> 66
A13: 12 | B13: ビットコインをはじめとする暗号資産の取引を支えている、取引履歴のデータを鎖のように繋いで管理する技術を何というでしょう？ | C13: ブロックチェーン | D13: ファイアウォール | E13: RSA暗号 | F13: マークルツリー | G13: =LEN(B13) -> 61
... A24: 23 | B24: 京都の緑寿庵清水が日本で唯一の専門店である、安土桃山時代にポルトガルから伝来した、表面に突起がついた小型の砂糖菓子は何でしょう？ | C24: 金平糖 | D24: ラムネ | E24: 風船ガム | F24: 飴玉 | G24: =LEN(B24) -> 64
A25: 24 | B25: 音が伝わる速さが速くなり、周波数が高くなることで起こる、ヘリウムガスを吸い込んだ際に声が高くなる現象を、あるキャラクターの名を使って何というでしょう？ | C25: ドナルドダック効果 | D25: ミッキーマウス効果 | E25: くまのプーさん効果 | F25: ティンカーベル効果 | G25: =LEN(中級!B25) -> 75
A26: 25 | B26: バスケットボールで、ボールを持った選手が、片足を軸足として固定し、もう片方の足を動かすテクニックを何というでしょう？ | C26: ピボット | D26: トラベリング | E26: アリウープ | F26: エアボール | G26: =LEN(中級!B26) -> 58
A27: 26 | B27: スター選手が揃った 2000 年代前半のチームは「銀河系軍団」と称され た、FC バルセロナとのダービー「エル・クラシコ」でも知られるスペイ ンのサッカークラブは何でしょう？ | C27: レアル・マドリード | D27: パリ・サンジェルマン | E27: ブライトンFC | F27: FCバルセロナ | G27: =LEN(初級!B35) -> 37
A28: 27 | B28: 下北沢のライブハウス「STARRY」を活動拠点としている、漫画『ぼっち・ざ・ろっく！』で主人公たちが結成するバンドは何でしょう？ | C28: 結束バンド | D28: 放課後ティータイム | E28: Poppin'Party | F28: μ's | G28: =LEN(中級!B28) -> 64
A29: 28 | B29: エドヒガンとオオシマザクラの交配で誕生した、気象庁がよく桜の開花予想宣言をする際の標本木としている桜の品種は何でしょう？ | C29: ソメイヨシノ | D29: シダレザクラ | E29: ヤエザクラ | F29: カスミザクラ | G29: =LEN(中級!B29) -> 60
A30: 29 | B30: 「ではみなさんは、そういうふうに川だと言いわれたり、乳の流ながれたあとだと言われたりしていた、このぼんやりと白いものがほんとうは何かご承知ですか」という書き出しで始まる、宮沢賢治の小説は何でしょう？ | C30: 『銀河鉄道の夜』 | D30: 『風の又三郎』 | E30: 『春と修羅』 | F30: 『注文の多い料理店』 | G30: =LEN(中級!B30) -> 99
A31: 30 | B31: AppleのiPhoneシリーズではiPhone15から採用される、「上下逆」の概念が解消され、高速データ転送や大容量電力供給などの特徴を備えたUSBの規格は何でしょう？ | C31: Type-C | D31: Type-A | E31: Type-B | F31: USB-D | G31: =LEN(中級!B31) -> 85
A32: 31 | B32: 鮎の縄張りの習性を利用して、おとりの鮎に針をつけて泳がせながら釣る方法を何というでしょう？ | C32: 友釣り | D32: 親釣り | E32: 恋釣り | F32: 影釣り | G32: =LEN(中級!B32) -> 45
A33: 32 | B33: 故郷の知多半島を舞台とした作品を多く残した、『おじいさんのランプ』や『ごんぎつね』などの代表作がある童話作家は誰でしょう？ | C33: 新美南吉 | D33: 椋鳩十 | E33: 斎藤隆介 | F33: あまんきみこ | G33: =LEN(中級!B33) -> 61
A34: 33 | B34: 毎年6月15日には生誕を祝う「青葉まつり」が高野山などで行われる、最澄とともに平安仏教を確立した僧は誰でしょう？ | C34: 空海 | D34: 法然 | E34: 親鸞 | F34: 栄西 | G34: =LEN(中級!B34) -> 56
A35: 34 | B35: 元々は氷を運ぶためのカバンだったことから、「運ぶ」を意味するアメリカの俗語が名前の由来となった、かばんの一種は何でしょう？ | C35: トートバッグ | D35: クラッチバッグ | E35: ナップザック | F35: ポシェット | G35: =LEN(中級!B35) -> 61
B36: 「特に水鳥の生息地として国際的に重要な湿地に関する条約」という条約を、1971年に採択された際のイランの都市にちなんで何というでしょう？ | C36: ラムサール条約 | D36: ウィーン条約 | E36: オスロ合意 | F36: マーストリヒト条約 | G36: =LEN(中級!B36) -> 68
A37: 36 | B37: 1997年にアメリカでDVDのオンラインレンタルサービスとして創業し、現在では契約者数2億人を超えるサブスク型の動画配信サービスを運営している会社は何でしょう？ | C37: Netflix | D37: Hulu | E37: Amazonプライム | F37: U-NEXT | G37: =LEN(中級!B37) -> 80
A38: 37 | B38: 独自の進化を遂げた固有種が多く存在し、ダーウィンが進化論の着想を得るきっかけとなったエクアドル領の島はどこでしょう？ | C38: ガラパゴス諸島 | D38: マダガスカル島 | E38: グリーンランド | F38: モルディブ | G38: =LEN(中級!B38) -> 58
A39: 38 | B39: ギリシャ語で「三日月」という意味である、メスシリンダーなどの容器の表面との相互作用によって形成される液面の屈曲は何でしょう？ | C39: メニスカス | D39: アモルファス | E39: ホメオスタシス | F39: セントラルドグマ | G39: =LEN(中級!B39) -> 62
A40: 39 | B40: バトミントンと同じ広さのコートで、3人1組の「レグ」というチームを組んで戦う、「足のバレーボール」ともいわれる東南アジア発祥のスポーツは何でしょう？ | C40: セパタクロー | D40: インディアカ | E40: クリケット | F40: ラクロス | G40: =LEN(中級!B40) -> 74
A41: 40 | B41: 「芸術は爆発だ」の名言で知られる、『傷ましき腕』、『太陽の塔』などの代表作で知られる芸術家は誰でしょう？ | C41: 岡本太郎 | D41: 草間彌生 | E41: 葛飾北斎 | F41: 横山大観 | G41: =LEN(中級!B41) -> 52
A42: 41 | B42: 本名は長谷川辰之助である、その筆名は「くたばってしまえ」が由来とされる、代表作『浮雲』で知られる小説家は誰でしょう？ | C42: 二葉亭四迷 | D42: 滝沢馬琴 | E42: 十返舎一九 | F42: 森鷗外 | G42: =LEN(中級!B42) -> 58
A43: 42 | B43: 発生したときは相手へ謝罪するのがマナーとされている、卓球で、台の端に当たりインになったボールのことを何というでしょう？ | C43: エッジボール | D43: ネットイン | E43: チキータ | F43: フィッシュ | G43: =LEN(中級!B43) -> 59
A44: 43 | B44: 一般的にはスネアドラムの左側に置くことが多い、2枚のシンバルを上下に組み合わせた楽器は何でしょう？ | C44: ハイハット | D44: スタックシンバル | E44: ライドシンバル | F44: クラッシュシンバル | G44: =LEN(中級!B44) -> 49
A45: 44 | B45: カナダの心理学者ダットンとアロンによって1974年に発表された、危ない所で感じるドキドキを恋愛感情だと勘違いしてしまう効果をなんというでしょう？ | C45: 吊り橋効果 | D45: バンジージャンプ効果 | E45: トンネル効果 | F45: 落とし穴効果 | G45: =LEN(中級!B45) -> 72
A46: 45 | B46: 科学者としてはパラシュートやヘリコプターの飛行原理を考案し、芸術家としては『最後の晩餐』や『モナ・リザ』といった名画を残した、ルネサンスの人物は誰でしょう？ | C46: レオナルド・ダ・ヴィンチ | D46: ミケランジェロ | E46: ボッティチェリ | F46: ラファエロ | G46: =LEN(中級!B46) -> 78
A47: 46 | B47: 舟の舳先に立ったローズが「I'm flying, Jack!」というシーンが特に有名な、1997年公開のジェームズ・キャメロン監督の映画は何でしょう？ | C47: 『タイタニック』 | D47: 『マトリックス』 | E47: 『E.T.』 | F47: 『アバター』 | G47: =LEN(中級!B47) -> 75
A48: 47 | B48: １，１，２、３、５，８と続く、数学で、最初の二項が1で、第三項以降の項がすべて直前の二項の和になっている数列を何というでしょう？ | C48: フィボナッチ数列 | D48: リュカ数列 | E48: コーシー数列 | F48: オイラー数列 | G48: =LEN(中級!B48) -> 64
... A101: 100 | B101: キリスト教で、父なる神、子なるイエス・キリスト、聖霊は本来同一のものであるとする教義を何というでしょう？ | C101: 三位一体 | D101: 御三家 | E101: 三種の神器 | F101: 三すくみ | G101: =LEN(中級!B101) -> 52

Sheet 上級
A1: 番号 | B1: 問題 | C1: 答え | D1: ダミー1 | E1: ダミー2 | F1: ダミー3 | G1: 文字数
A2: 1 | B2: 1932年に女性として初めて大西洋横断単独無着陸飛行を成功させたものの、1937年には世界一周の挑戦中に行方不明となった、アメリカのパイロットは誰でしょう？ | C2: アメリア・イアハート | D2: セルマ・ラーゲルレーヴ | E2: ワレンチナ・テレシコワ | F2: フィンボガドゥティル | G2: =LEN(B2) -> 78
A3: 2 | B3: 独ソ戦のさなか、ドイツ軍によって母親と故郷を奪われた主人公セラフィマが復讐のために狙撃兵となって過酷な戦場を生き抜くさまを描いた、逢坂冬馬の小説は何でしょう？ | C3: 『同士少女よ、敵を撃て』 | D3: 『誰が為に鐘は鳴る』 | E3: 『地獄の黙示録』 | F3: 『ラーゲリより愛を込めて』 | G3: =LEN(B3) -> 79
A4: 3 | B4: 1919年、ドイツのヴァルター・グロピウスによって創設され、ミース・ファン・デル・ローエなどが教鞭をとった、美術と建築に関する総合的な教育を行った学校は何でしょう？ | C4: バウハウス | D4: ハウステンボス | E4: マチュ・ピチュ | F4: モヘンジョ・ダロ | G4: =LEN(B4) -> 82
A5: 4 | B5: 1917年の設立時は東京・駒込に、現在は埼玉県和光市に本部を置いている、自然科学に関する幅広い研究を行っている研究所はどこでしょう？ | C5: 理化学研究所 | D5: 国立天文台 | E5: 日本科学未来館 | F5: JAXA | G5: =LEN(B5) -> 66
A6: 5 | B6: 「鉢の腰」とも呼ばれる、砂時計の中央部にあるくびれた部分のことを、「開口部」を意味する英語から何というでしょう？ | C6: オリフィス | D6: ファウスト | E6: ファンデーション | F6: フォレスト | G6: =LEN(B6) -> 56
A7: 6 | B7: 鼻中隔の前側にあり、毛細血管が多く集まっているため鼻血が出やすい部位のことを、ドイツの解剖学者の名から何というでしょう？ | C7: キーゼルバッハ部位 | D7: ランゲルハンス島 | E7: アランチウス間 | F7: ライディッヒ細胞 | G7: =LEN(B7) -> 60
A8: 7 | B8: ガラスやゴムなどにみられ、日本語では「非晶質」とも呼ばれる、物質を構成する原子が不規則に配列した状態を何というでしょう？ | C8: アモルファス | D8: メニスカス | E8: モノクリニック | F8: オルソロンビック | G8: =LEN(B8) -> 60
A9: 8 | B9: 「代理人」という意味がある、第三者が国民の行政に対する苦情を受け付け、中立的な立場から迅速に問題を解決するための制度を何というでしょう？ | C9: オンブズマン制度 | D9: クオーター制度 | E9: デポジット制度 | F9: ストックオプション制度 | G9: =LEN(B9) -> 68
A10: 9 | B10: 与謝野晶子との間で、働く女性に関する「母性保護論争」を繰り広げた、女性文芸誌『青鞜(せいとう)』を創刊した婦人運動家は誰でしょう？ | C10: 平塚らいてう | D10: 中山マサ | E10: 津田梅子 | F10: 市川房枝 | G10: =LEN(B10) -> 65
A11: 10 | B11: 「science」を「科学」、「philosophy」を「哲学」と翻訳し、日本における「哲学の父」と呼ばれた、津和野藩出身の明治の思想家は誰でしょう？ | C11: 西周 | D11: 森鴎外 | E11: 二葉亭四迷 | F11: 西田幾多郎 | G11: =LEN(B11) -> 75
A12: 11 | B12: 生涯に1,500種類以上の植物を命名し、「雑草という草はない」という名言を残した、「日本植物学の父」と呼ばれる植物学者は誰でしょう？ | C12: 牧野富太郎 | D12: 中谷宇吉郎 | E12: 高柳健次郎 | F12: 北里柴三郎 | G12: =LEN(B12) -> 66
A13: 12 | B13: 「近代日本医学の父」とも呼ばれ、ペスト菌の発見や破傷風の治療法を発明した功績で知られる人物で、2024年度より発行される1000円札紙幣に描かれている人物は誰でしょう? | C13: 北里柴三郎 | D13: 牧野富太郎 | E13: 中谷宇吉郎 | F13: 高柳健次郎 | G13: =LEN(B13) -> 84
... A64: 63 | B64: 和歌などの学芸にも優れ、豊臣秀吉からは「鄙（ひな）の華人」と絶賛された、「独眼竜」の異名で知られる東北地方の戦国武将は誰でしょう？ | C64: 伊達政宗 | D64: 武田信玄 | E64: 上杉謙信 | F64: 毛利元就 | G64: =LEN(B64) -> 65
A65: 64 | B65: 1月にグラナダの陥落にともなってレコンキスタが完了し、10月にコロンブスがアメリカ大陸へとたどり着いたのは、西暦何年のことでしょう？ | C65: 1492年 | D65: 1592年 | E65: 1392年 | F65: 1692年 | G65: =LEN(B64) -> 65
A66: 65 | B66: 飛行機に乗っているときなどに起こりうる、食事や水分を十分にとらずに長時間座ったままでいると、血行不良が起こり血が固まりやすくなる症状のことを何というでしょう？ | C66: エコノミークラス症候群 | D66: ビジネスクラス症候群 | E66: ファーストクラス症候群 | F66: グリーンクラス症候群 | G66: =LEN(B66) -> 79
A67: 66 | B67: トリックアートで、覗き穴から片目で見ると、左側にいる人ほど小さく、右側にいる人ほど大きく見える部屋のことを、これを発明したアメリカの科学者の名前から何というでしょう？ | C67: エイムズの部屋 | D67: ペンローズの部屋 | E67: エッシャーの部屋 | F67: ダリの部屋 | G67: =LEN(B67) -> 83
A68: 67 | B68: 最初の犠牲者は製作者本人のペラリウスであった、古代ギリシャで用いられ、中に入れられた人間の叫び声がある動物の鳴き声に聞こえることからそう呼ばれる、拷問器具の一種は何でしょう？ | C68: ファラリスの雄牛 | D68: パブロフの犬 | E68: ジョハリの窓 | F68: ダモクレスの剣 | G68: =LEN(B68) -> 87
A69: 68 | B69: 別名「社会的手抜き」とも呼ばれる、共同作業をする人数が増えるごとに各個人の作業の貢献度が低下する現象を、提唱したフランスの農学者の名前から何というでしょう？ | C69: リンゲルマン効果 | D69: ゴーレム効果 | E69: ピグマリオン効果 | F69: バンドワゴン効果 | G69: =LEN(B69) -> 78
A70: 69 | B70: 著書『われはロボット』の中で、有名な「ロボット三原則」を提唱した、その他の代表作に、「銀河百科辞典」が登場する『ファウンデーション』シリーズがある作家は誰でしょう？ | C70: アイザック・アシモフ | D70: サン・テグジュペリ | E70: アーサー・C・クラーク | F70: フィリップ・K・ディック | G70: =LEN(B70) -> 82
A71: 70 | B71: ゲーム理論のうちの非協力ゲームの基本概念で、すべてのゲームの参加者が一定のルールのもと、自らの利得が最大となる最適な戦略を選択し合っている状態のことを何というでしょう？ | C71: ナッシュ均衡 | D71: パレート最適 | E71: ラッシュ的納得 | F71: モスト座標 | G71: =LEN(B71) -> 84
A72: 71 | B72: 2022年5月には初の英訳版である『Handbook of Scientific Tables』が刊行された、毎年国立天文台が編纂しているデータブックは何？ | C72: 理科年表 | D72: 星座早見盤 | E72: レッドリスト | F72: ブルーバックス | G72: =LEN(B72) -> 78
A73: 72 | B73: 現地の言葉で「死者の丘」という意味がある、パキスタンのインダス川流域にあるインダス文明最大級の都市遺跡は何でしょう？ | C73: モヘンジョ・ダロ | D73: マチュ・ピチュ | E73: タージ・マハル | F73: ボロブドゥール移籍 | G73: =LEN(B73) -> 58
A74: 73 | B74: 映画『奇蹟がくれた数式』にその生涯が描かれている、3000以上もの数学の公式を考案し、「インドの魔術師」の異名を持った数学者は誰でしょう？ | C74: ラマヌジャン | D74: シャノン | E74: ディオファントス | F74: ヒルベルト | G74: =LEN(B74) -> 69
A75: 74 | B75: 『刺青殺人事件』で初登場した、江戸川乱歩の「明智小五郎」、横溝正史の「金田一耕助」と並んで「日本三大名探偵」と称される、高木彬光が生み出した名探偵は誰でしょう？ | C75: 神津恭介 | D75: 久能整 | E75: 御手洗潔 | F75: シャーロック・ホームズ | G75: =LEN(B75) -> 80
A76: 75 | B76: イルカやクジラの頭部にある、超音波を集め前方に放射することで、コミュニケーションやエコーロケーションを行う、生物の器官は何でしょう？ | C76: メロン器官 | D76: バナナ器官 | E76: オレンジ器官 | F76: グレープ器官 | G76: =LEN(B76) -> 66
A77: 76 | B77: 「開放」「盲点」「秘密」「未知」の4つの分類がある、コミュニケーションの円滑な進め方と自己の公開を模索するため提唱された考え方のことを、提唱した二人の心理学者の合成名で何というでしょう？ | C77: ジョハリの窓 | D77: ヒュギエイアの盃 | E77: パブロフの犬 | F77: ダモクレスの剣 | G77: =LEN(B77) -> 93
... A101: 100 | B101: 遣隋使の小野妹子が謁見した、大運河の建設や 3 度にわたる高句麗遠征をおこなった、中国・隋の第2代皇帝は誰でしょう？ | C101: 煬帝 | D101: 文帝 | E101: 恭帝侑 | F101: 武帝 | G101: =LEN(B101) -> 58
